<mujoco model="panda">
    <actuator>
        <motor ctrllimited="true" ctrlrange="-80.0 80.0" joint="robot0_joint1" name="robot0_torq_j1" />
        <motor ctrllimited="true" ctrlrange="-80.0 80.0" joint="robot0_joint2" name="robot0_torq_j2" />
        <motor ctrllimited="true" ctrlrange="-80.0 80.0" joint="robot0_joint3" name="robot0_torq_j3" />
        <motor ctrllimited="true" ctrlrange="-80.0 80.0" joint="robot0_joint4" name="robot0_torq_j4" />
        <motor ctrllimited="true" ctrlrange="-80.0 80.0" joint="robot0_joint5" name="robot0_torq_j5" />
        <motor ctrllimited="true" ctrlrange="-12.0 12.0" joint="robot0_joint6" name="robot0_torq_j6" />
        <motor ctrllimited="true" ctrlrange="-12.0 12.0" joint="robot0_joint7" name="robot0_torq_j7" />
    <position ctrllimited="true" ctrlrange="0.0 0.04" forcelimited="true" forcerange="-20 20" joint="gripper0_finger_joint1" kp="1000" name="gripper0_gripper_finger_joint1" />
        <position ctrllimited="true" ctrlrange="-0.04 0.0" forcelimited="true" forcerange="-20 20" joint="gripper0_finger_joint2" kp="1000" name="gripper0_gripper_finger_joint2" />
    </actuator>
    <asset>
        <mesh file="/home/aries/Dropbox/research/recovery-skills/robosuite/robosuite/models/assets/robots/panda/meshes/link0.stl" name="robot0_link0" />
        <mesh file="/home/aries/Dropbox/research/recovery-skills/robosuite/robosuite/models/assets/robots/panda/meshes/link1.stl" name="robot0_link1" />
        <mesh file="/home/aries/Dropbox/research/recovery-skills/robosuite/robosuite/models/assets/robots/panda/meshes/link2.stl" name="robot0_link2" />
        <mesh file="/home/aries/Dropbox/research/recovery-skills/robosuite/robosuite/models/assets/robots/panda/meshes/link3.stl" name="robot0_link3" />
        <mesh file="/home/aries/Dropbox/research/recovery-skills/robosuite/robosuite/models/assets/robots/panda/meshes/link4.stl" name="robot0_link4" />
        <mesh file="/home/aries/Dropbox/research/recovery-skills/robosuite/robosuite/models/assets/robots/panda/meshes/link5.stl" name="robot0_link5" />
        <mesh file="/home/aries/Dropbox/research/recovery-skills/robosuite/robosuite/models/assets/robots/panda/meshes/link6.stl" name="robot0_link6" />
        <mesh file="/home/aries/Dropbox/research/recovery-skills/robosuite/robosuite/models/assets/robots/panda/meshes/link7.stl" name="robot0_link7" />
        <mesh file="/home/aries/Dropbox/research/recovery-skills/robosuite/robosuite/models/assets/robots/panda/meshes/link0_vis.stl" name="robot0_link0_vis" />
        <mesh file="/home/aries/Dropbox/research/recovery-skills/robosuite/robosuite/models/assets/robots/panda/meshes/link1_vis.stl" name="robot0_link1_vis" />
        <mesh file="/home/aries/Dropbox/research/recovery-skills/robosuite/robosuite/models/assets/robots/panda/meshes/link2_vis.stl" name="robot0_link2_vis" />
        <mesh file="/home/aries/Dropbox/research/recovery-skills/robosuite/robosuite/models/assets/robots/panda/meshes/link3_vis.stl" name="robot0_link3_vis" />
        <mesh file="/home/aries/Dropbox/research/recovery-skills/robosuite/robosuite/models/assets/robots/panda/meshes/link4_vis.stl" name="robot0_link4_vis" />
        <mesh file="/home/aries/Dropbox/research/recovery-skills/robosuite/robosuite/models/assets/robots/panda/meshes/link5_vis.stl" name="robot0_link5_vis" />
        <mesh file="/home/aries/Dropbox/research/recovery-skills/robosuite/robosuite/models/assets/robots/panda/meshes/link6_vis.stl" name="robot0_link6_vis" />
        <mesh file="/home/aries/Dropbox/research/recovery-skills/robosuite/robosuite/models/assets/robots/panda/meshes/link7_vis.stl" name="robot0_link7_vis" />
    <mesh file="/home/aries/Dropbox/research/recovery-skills/robosuite/robosuite/models/assets/mounts/meshes/rethink_mount/pedestal.stl" name="mount0_pedestal" />
    <mesh file="/home/aries/Dropbox/research/recovery-skills/robosuite/robosuite/models/assets/grippers/meshes/panda_gripper/hand.stl" name="gripper0_hand" />
        <mesh file="/home/aries/Dropbox/research/recovery-skills/robosuite/robosuite/models/assets/grippers/meshes/panda_gripper/hand_vis.stl" name="gripper0_hand_vis" />
        <mesh file="/home/aries/Dropbox/research/recovery-skills/robosuite/robosuite/models/assets/grippers/meshes/panda_gripper/finger.stl" name="gripper0_finger" />
        <mesh file="/home/aries/Dropbox/research/recovery-skills/robosuite/robosuite/models/assets/grippers/meshes/panda_gripper/finger_vis.stl" name="gripper0_finger_vis" />
        <mesh file="/home/aries/Dropbox/research/recovery-skills/robosuite/robosuite/models/assets/grippers/meshes/panda_gripper/finger_longer.stl" name="gripper0_finger_vis2" />
    </asset>
    <worldbody>
        <body name="robot0_base" pos="-0.56 0.0 0.912">

            <camera mode="fixed" name="robot0_robotview" pos="1.0 0 0.4" quat="0.653 0.271 0.271 0.653" />
            <inertial diaginertia="0 0 0" mass="0" pos="0 0 0" />

            <body name="robot0_link0" pos="0 0 0">
                <inertial diaginertia="0.4 0.4 0.4" mass="4" pos="0 0 0.05" />
                <geom conaffinity="0" contype="0" group="1" mesh="robot0_link0_vis" name="robot0_link0_visual" rgba="1 1 1 1" type="mesh" />
                <geom group="0" mesh="robot0_link0" name="robot0_link0_collision" rgba="0 0.5 0 1" type="mesh" />
                <body name="robot0_link1" pos="0 0 0.333">
                    <inertial diaginertia="0.3 0.3 0.3" mass="3" pos="0 0 -0.07" />
                    <joint armature="5.0" axis="0 0 1" damping="0.1" frictionloss="0.1" limited="true" name="robot0_joint1" pos="0 0 0" range="-2.8973 2.8973" />
                    <geom conaffinity="0" contype="0" group="1" mesh="robot0_link1_vis" name="robot0_link1_visual" rgba="1 1 1 1" type="mesh" />
                    <geom group="0" mesh="robot0_link1" name="robot0_link1_collision" rgba="0 0.5 0 1" type="mesh" />
                    <body name="robot0_link2" pos="0 0 0" quat="0.707107 -0.707107 0 0">
                        <inertial diaginertia="0.3 0.3 0.3" mass="3" pos="0 -0.1 0" />
                        <joint armature="2.5" axis="0 0 1" damping="0.1" frictionloss="0.1" limited="true" name="robot0_joint2" pos="0 0 0" range="-1.7628 1.7628" />
                        <geom conaffinity="0" contype="0" group="1" mesh="robot0_link2_vis" name="robot0_link2_visual" rgba="1 1 1 1" type="mesh" />
                        <geom group="0" mesh="robot0_link2" name="robot0_link2_collision" rgba="0 0.5 0 1" type="mesh" />
                        <body name="robot0_link3" pos="0 -0.316 0" quat="0.707107 0.707107 0 0">
                            <inertial diaginertia="0.2 0.2 0.2" mass="2" pos="0.04 0 -0.05" />
                            <joint armature="1.6666666666666667" axis="0 0 1" damping="0.1" frictionloss="0.1" limited="true" name="robot0_joint3" pos="0 0 0" range="-2.8973 2.8973" />
                            <geom conaffinity="0" contype="0" group="1" mesh="robot0_link3_vis" name="robot0_link3_visual" rgba="1 1 1 1" type="mesh" />
                            <geom group="0" mesh="robot0_link3" name="robot0_link3_collision" rgba="0 0.5 0 1" type="mesh" />
                            <body name="robot0_link4" pos="0.0825 0 0" quat="0.707107 0.707107 0 0">
                                <inertial diaginertia="0.2 0.2 0.2" mass="2" pos="-0.04 0.05 0" />
                                <joint armature="1.25" axis="0 0 1" damping="0.1" frictionloss="0.1" limited="true" name="robot0_joint4" pos="0 0 0" range="-3.0718 -0.0698" />
                                <geom conaffinity="0" contype="0" group="1" mesh="robot0_link4_vis" name="robot0_link4_visual" rgba="1 1 1 1" type="mesh" />
                                <geom group="0" mesh="robot0_link4" name="robot0_link4_collision" rgba="0 0.5 0 1" type="mesh" />
                                <body name="robot0_link5" pos="-0.0825 0.384 0" quat="0.707107 -0.707107 0 0">
                                    <inertial diaginertia="0.2 0.2 0.2" mass="2" pos="0 0 -0.15" />
                                    <joint armature="1.0" axis="0 0 1" damping="0.1" frictionloss="0.1" limited="true" name="robot0_joint5" pos="0 0 0" range="-2.8973 2.8973" />
                                    <geom conaffinity="0" contype="0" group="1" mesh="robot0_link5_vis" name="robot0_link5_visual" rgba="1 1 1 1" type="mesh" />
                                    <geom group="0" mesh="robot0_link5" name="robot0_link5_collision" rgba="0 0.5 0 1" type="mesh" />
                                    <body name="robot0_link6" pos="0 0 0" quat="0.707107 0.707107 0 0">
                                        <inertial diaginertia="0.1 0.1 0.1" mass="1.5" pos="0.06 0 0" />
                                        <joint armature="0.8333333333333334" axis="0 0 1" damping="0.01" frictionloss="0.1" limited="true" name="robot0_joint6" pos="0 0 0" range="-0.0175 3.7525" />
                                        <geom conaffinity="0" contype="0" group="1" mesh="robot0_link6_vis" name="robot0_link6_visual" rgba="1 1 1 1" type="mesh" />
                                        <geom group="0" mesh="robot0_link6" name="robot0_link6_collision" rgba="0 0.5 0 1" type="mesh" />
                                        <body name="robot0_link7" pos="0.088 0 0" quat="0.707107 0.707107 0 0">
                                            <inertial diaginertia="0.05 0.05 0.05" mass="0.5" pos="0 0 0.08" />
                                            <joint armature="0.7142857142857143" axis="0 0 1" damping="0.01" frictionloss="0.1" limited="true" name="robot0_joint7" pos="0 0 0" range="-2.8973 2.8973" />
                                            <geom conaffinity="0" contype="0" group="1" mesh="robot0_link7_vis" name="robot0_link7_visual" rgba="1. 1. 1. 1." type="mesh" />
                                            <geom group="0" mesh="robot0_link7" name="robot0_link7_collision" rgba="0 0.5 0 1" type="mesh" />

                                            <body name="robot0_right_hand" pos="0 0 0.1065" quat="0.924 0 0 -0.383">
                                                <inertial diaginertia="0.05 0.05 0.05" mass="0.5" pos="0 0 0" />

                                                <camera fovy="75" mode="fixed" name="robot0_eye_in_hand" pos="0.05 0 0" quat="0 0.707108 0.707108 0" />

                                            <body name="gripper0_right_gripper" pos="0 0 0" quat="0.707107 0 0 -0.707107">
                                                <site group="1" name="gripper0_ft_frame" pos="0 0 0" rgba="1 0 0 1" size="0.01 0.01 0.01" type="sphere" />
                                                <inertial diaginertia="0.09 0.07 0.05" mass="0.3" pos="0 0 0.17" quat="0.707107 0.707107 0 0" />
                                                <geom conaffinity="0" contype="0" group="1" mesh="gripper0_hand_vis" name="gripper0_hand_visual" pos="0 0 0." quat="0.707107 0 0 0.707107" rgba="1 1 1 1" type="mesh" />
                                                <geom group="0" mesh="gripper0_hand" name="gripper0_hand_collision" pos="0 0 0." quat="0.707107 0 0 0.707107" rgba="0 0 0.5 1" type="mesh" />

                                                <body name="gripper0_eef" pos="0 0 0.097" quat="1 0 0 0">
                                                    <site group="1" name="gripper0_grip_site" pos="0 0 0" rgba="1 0 0 0.5" size="0.01 0.01 0.01" type="sphere" />
                                                    <site group="1" name="gripper0_ee_x" pos="0.1 0 0" quat="0.707105  0 0.707108 0 " rgba="1 0 0 0" size="0.005 .1" type="cylinder" />
                                                    <site group="1" name="gripper0_ee_y" pos="0 0.1 0" quat="0.707105 0.707108 0 0" rgba="0 1 0 0" size="0.005 .1" type="cylinder" />
                                                    <site group="1" name="gripper0_ee_z" pos="0 0 0.1" quat="1 0 0 0" rgba="0 0 1 0" size="0.005 .1" type="cylinder" />

                                                    <site group="1" name="gripper0_grip_site_cylinder" pos="0 0 0" rgba="0 1 0 0.3" size="0.005 10" type="cylinder" />
                                                </body>
                                                <body name="gripper0_leftfinger" pos="0 0 0.0524" quat="0.707107 0 0 0.707107">
                                                    <inertial diaginertia="0.01 0.01 0.005" mass="0.1" pos="0 0 0.05" />
                                                    <joint armature="1.0" axis="0 1 0" damping="100" frictionloss="1.0" limited="true" name="gripper0_finger_joint1" pos="0 0 0" range="0.0 0.04" type="slide" />
                                                    <geom conaffinity="0" contype="0" group="1" mesh="gripper0_finger_vis" name="gripper0_finger1_visual" rgba="0.499 0.499 0.499 1" type="mesh" />
                                                    <geom conaffinity="1" condim="4" contype="0" friction="1 0.005 0.0001" group="0" mesh="gripper0_finger" name="gripper0_finger1_collision" rgba="0 0 0.5 1" solref="0.02 1" type="mesh" />
                                                    <body name="gripper0_finger_joint1_tip" pos="0 0.0085 0.056">
                                                        <inertial diaginertia="0.01 0.01 0.01" mass="0.01" pos="0 0 0" quat="0 0 0 1" />
                                                        <geom conaffinity="1" contype="1" friction="2 0.05 0.0001" group="0" name="gripper0_finger1_pad_collision" pos="0 -0.005 -0.015" quat="0 0 0 1" rgba="0 0 0.5 1" size="0.008 0.004 0.008" solref="0.01 0.5" type="box" />
                                                    </body>
                                                </body>
                                                <body name="gripper0_rightfinger" pos="0 0 0.0524" quat="0.707107 0 0 0.707107">
                                                    <inertial diaginertia="0.01 0.01 0.005" mass="0.1" pos="0 0 0.05" />
                                                    <joint armature="1.0" axis="0 1 0" damping="100" frictionloss="1.0" limited="true" name="gripper0_finger_joint2" pos="0 0 0" range="-0.04 0.0" type="slide" />
                                                    <geom conaffinity="0" contype="0" group="1" mesh="gripper0_finger_vis" name="gripper0_finger2_visual" quat="0 0 0 1" rgba="0.499 0.499 0.499 1" type="mesh" />
                                                    <geom conaffinity="1" condim="4" contype="0" friction="1 0.005 0.0001" group="0" mesh="gripper0_finger" name="gripper0_finger2_collision" quat="0 0 0 1" rgba="0 0 0.5 1" solref="0.02 1" type="mesh" />
                                                    <body name="gripper0_finger_joint2_tip" pos="0 -0.0085 0.056">
                                                        <inertial diaginertia="0.01 0.01 0.01" mass="0.01" pos="0 0 0" quat="0 0 0 1" />
                                                        <geom conaffinity="1" contype="1" friction="2 0.05 0.0001" group="0" name="gripper0_finger2_pad_collision" pos="0 0.005 -0.015" quat="0 0 0 1" rgba="0 0 0.5 1" size="0.008 0.004 0.008" solref="0.01 0.5" type="box" />
                                                    </body>
                                                </body>
                                            </body>
                                        </body>
                                        </body>
                                    </body>
                                </body>
                            </body>
                        </body>
                    </body>
                </body>
            </body>
            <body name="mount0_base" pos="0.0 0.0 0.01">
                <body name="mount0_controller_box" pos="0 0 0">
                    <inertial diaginertia="1.71363 1.27988 0.809981" mass="46.64" pos="-0.325 0 -0.38" />
                    <geom name="mount0_controller_box_col" pos="-0.325 0 -0.38" rgba="0.5 0.5 0 1" size="0.11 0.2 0.265" type="box" />
                </body>
                <body name="mount0_pedestal_feet" pos="0 0 0">
                    <inertial diaginertia="8.16095 9.59375 15.0785" mass="167.09" pos="-0.1225 0 -0.758" />
                    <geom name="mount0_pedestal_feet_col" pos="-0.1225 0 -0.758" rgba="0.5 0.5 0 1" size="0.385 0.35 0.155" type="box" />
                </body>
                <body name="mount0_torso" pos="0 0 0">
                    <inertial diaginertia="1e-08 1e-08 1e-08" mass="0.0001" pos="0 0 0" />
                    <geom conaffinity="0" contype="0" group="1" name="mount0_torso_vis" pos="0 0 -0.05" rgba="0.2 0.2 0.2 1" size="0.05 0.05 0.05" type="box" />
                </body>
                <body name="mount0_pedestal" pos="0 0 0">
                    <inertial diaginertia="6.0869 5.81635 4.20915" mass="60.864" pos="0 0 0" quat="0.659267 -0.259505 -0.260945 0.655692" />
                    <geom conaffinity="0" contype="0" group="1" mesh="mount0_pedestal" name="mount0_pedestal_vis" rgba="0.2 0.2 0.2 1" type="mesh" />
                    <geom name="mount0_pedestal_col" pos="-0.02 0 -0.29" rgba="0.5 0.5 0 1" size="0.18 0.31" type="cylinder" />
                </body>
            </body>
        </body>
    </worldbody>
    <sensor>
        <force name="gripper0_force_ee" site="gripper0_ft_frame" />
        <torque name="gripper0_torque_ee" site="gripper0_ft_frame" />
    </sensor>
</mujoco>
