<?xml version="1.0" encoding="utf-8"?>
<mujoco model="door_knob">
	<compiler angle="radian"/>
	<visual>
		<map fogend="5" fogstart="3" force="0.1" zfar="10" znear="0.01"/>
		<quality shadowsize="2048"/>
		<global offheight="256" offwidth="256"/>
	</visual>
	<asset>
		<mesh file="../../door/leverknobs/1552166919/body_1.stl" name="door_knob_1" scale="0.0015 0.0015 0.0015"/>
		<mesh file="../../door/leverknobs/1552166919/body_2.stl" name="door_knob_2" scale="0.0015 0.0015 0.0015"/>
		<mesh file="../../door/leverknobs/1552166919/body_3.stl" name="door_knob_3" scale="0.0015 0.0015 0.0015"/>
		<mesh file="../../door/leverknobs/1552166919/body_4.stl" name="door_knob_4" scale="0.0015 0.0015 0.0015"/>
		<mesh file="../../door/leverknobs/1552166919/body_5.stl" name="door_knob_5" scale="0.0015 0.0015 0.0015"/>
		<texture builtin="flat" height="32" name="wall_geom" type="2d" width="32"/>
		<texture builtin="flat" height="32" name="frame_geom" type="2d" width="32"/>
		<texture builtin="flat" height="32" name="door_geom" type="2d" width="32"/>
		<texture builtin="flat" height="32" name="knob_geom" type="2d" width="32"/>
		<texture builtin="gradient" height="128" rgb1="0.4 0.6 0.8" rgb2="0 0 0" type="skybox" width="128"/>
		<texture builtin="gradient" height="512" name="texplane" rgb1="0.16 0.03 0.05" rgb2="0.33 0.22 0.39" type="2d" width="512"/>
		<material name="Paint" shininess="0.2" specular="0.34" texture="wall_geom"/>
		<material name="Wood" shininess="0.17" specular="0.18" texture="frame_geom"/>
		<material name="Carpet" shininess="0.01" specular="0.03" texture="door_geom"/>
		<material name="Metal" shininess="0.91" specular="0.92" texture="knob_geom"/>
		<material name="Floor" texture="texplane"/>
	</asset>
	<contact>
		<pair geom1="knob_latch" geom2="door_frame_0" solref="0.01 1"/>
		<pair geom1="knob_latch" geom2="door_frame_1" solref="0.01 1"/>
		<pair geom1="knob_latch" geom2="door_frame_2" solref="0.01 1"/>
		<pair geom1="knob_latch" geom2="door_frame_3" solref="0.01 1"/>
	</contact>
	<default>
		<joint armature="1" damping="1" limited="true"/>
		<default class="wall">
			<geom rgba="0.17 0.51 0.08 1.0" type="mesh"/>
		</default>
		<default class="frame">
			<geom rgba="0.76 0.82 0.71 1.0" type="mesh"/>
		</default>
		<default class="door">
			<geom rgba="0.74 0.24 0.31 1.0" type="mesh"/>
		</default>
		<default class="door_knob">
			<geom condim="4" rgba="0.29 0.43 0.58 1.0" type="mesh"/>
		</default>
		<default class="robot">
			<joint damping="0.09"/>
		</default>
	</default>
	<worldbody>
		<light diffuse="1.0 0.9 1.0" dir="-0.12 0.13 -0.28" directional="true" pos="4.83 -3.68 3.1"/>
		<light diffuse="1.0 1.0 1.0" dir="0.37 -0.14 -0.43" directional="true" pos="0.25 2.69 5.15"/>
		<geom material="Floor" name="floor" pos="0 0 -0.05" size="15.0 15.0 0.05" type="plane"/>
		<camera fovy="60" mode="fixed" name="camera1" pos="0.99 0.5 1.0" euler="0.0 1.57 1.57"/>
		<camera fovy="60" mode="fixed" name="camera2" pos="0.5 0.0 1.99" euler="0 0 0"/>
		<body childclass="wall" name="wall_link" pos="0.0 0.0 0.0">
			<inertial mass="100" pos="0 0 0" diaginertia="0.0001 0.0001 0.0001"/>
			<geom material="Wood" name="wall_0" pos="-0.15 -1.57 1.2005000000000001" size="0.15 1.0 1.2005000000000001" type="box" euler="0 0 0"/>
			<geom material="Wood" name="wall_1" pos="-0.15 1.6 1.2005000000000001" size="0.15 1.0 1.2005000000000001" type="box" euler="0 0 0"/>
			<geom material="Wood" name="wall_2" pos="-0.15 0 2.9010000000000002" size="0.15 2.6 0.5" type="box" euler="0 0 0"/>
			<body childclass="frame" name="frame_link" pos="0 -0.35 1">
				<inertial mass="500" pos="0 0 0" diaginertia="0.0001 0.0001 0.0001"/>
				<geom material="Wood" name="door_frame_0" pos="0 -0.21000000000000002 0.20050000000000012" size="0.0115 0.05 1.2005000000000001" type="box" euler="0 0 0"/>
				<geom material="Wood" name="door_frame_1" pos="0 0.91 0.20050000000000012" size="0.0115 0.05 1.2005000000000001" type="box" euler="0 0 0"/>
				<geom material="Wood" name="door_frame_2" pos="0 0.35 1.3510000000000002" size="0.0115 0.6 0.05" type="box" euler="0 0 0"/>
				<geom material="Wood" name="door_frame_3" pos="-0.042499999999999996 -0.21000000000000002 0.20050000000000012" size="0.0115 0.05 1.2005000000000001" type="box" euler="0 0 0"/>
				<geom material="Wood" name="door_frame_4" pos="-0.042499999999999996 0.91 0.20050000000000012" size="0.0115 0.05 1.2005000000000001" type="box" euler="0 0 0"/>
				<geom material="Wood" name="door_frame_5" pos="-0.042499999999999996 0.35 1.3510000000000002" size="0.0115 0.6 0.05" type="box" euler="0 0 0"/>
				<body childclass="door" name="door_link" pos="0 0 0">
					<joint armature="0.0001" axis="0 0 1" damping="1.0" frictionloss="0" limited="true" name="hinge0" pos="0 0.85 0" range="-0.0 1.57" stiffness="0.11" type="hinge"/>
					<geom material="Wood" name="door0" pos="0 0.35 0.15050000000000008" size="0.0115 0.5 1.138995" type="box" euler="0 0 0"/>
					<inertial mass="15.876900000000001" pos="0 0.35 0.15050000000000008" diaginertia="8.328229218075002 7.005854124750002 1.323774906675"/>
					<body childclass="door_knob" name="knob_link" pos="0 0 0">
						<inertial mass="1" pos="0 0 0" diaginertia="0.001 0.001 0.001"/>
						<joint armature="0" axis="0 1 0" damping="30000" frictionloss="0" limited="true" name="target0" range="-0.2 0.3" stiffness="0" type="slide"/>
						<joint armature="0" axis="0 0 1" damping="30000" frictionloss="0" limited="true" name="target1" range="-0.5 0.5" stiffness="0" type="slide"/>
						<joint armature="0.0001" axis="1 0 0" damping="1.17" frictionloss="0" limited="true" name="hinge1" pos="0 0 0" range="-1.378111111111111 1.378111111111111" stiffness="1.25" type="hinge"/>
						<body childclass="door_knob" name="leverknob_link" pos="0.0115 0 0">
							<geom friction="0.81 0.003 0.001" material="Wood" mesh="door_knob_1" name="door_knob_1" euler="-1.57 1.57 0"/>
							<geom friction="0.81 0.003 0.001" material="Wood" mesh="door_knob_2" name="door_knob_2" euler="-1.57 1.57 0"/>
							<geom friction="0.81 0.003 0.001" material="Wood" mesh="door_knob_3" name="door_knob_3" euler="-1.57 1.57 0"/>
							<geom friction="0.81 0.003 0.001" material="Wood" mesh="door_knob_4" name="door_knob_4" euler="-1.57 1.57 0"/>
							<geom friction="0.81 0.003 0.001" material="Wood" mesh="door_knob_5" name="door_knob_5" euler="-1.57 1.57 0"/>
							<geom material="Paint" name="knob_latch" pos="-0.03275 0 0" size="0.0075 0.18333333333333332 0.05" type="box" euler="0 0 0"/>
							<inertial mass="1" pos="-0.058050000000000004 0 0" diaginertia="0.003009259259259259 0.00022708333333333337 0.0028196759259259256"/>
						</body>
					</body>
				</body>
			</body>
		</body>
	</worldbody>
</mujoco>
